Workbook

Sheet Dashboard
B1: INVENTORY DASHBOARD | N1: PROFIT DASHBOARD
C4: Stock Unit | F4: Inventory Value | I4: Potential Revenue
C5: =SUM(Product_Master!O:O) -> 1436 | F5: =SUM(Product_Master!U:U) -> 4530190
B8: Date | C8: Sum of Quantity
B9: 46190 | C9: 37
B10: 46191 | C10: 5 | O10: #VALUE!
B11: 46192 | C11: 1
B12: 46193 | C12: 5
B13: 46194 | C13: 1
B14: 46195 | C14: 6 | S14: Due Invoices (Payable)
B15: 46196 | C15: 4 | S15: Due | T15: Supplier | U15: Amount
B16: 46197 | C16: 2 | P16: Reorder Status | Q16: (All) | S16: {=_xlfn._xlws.SORT(_xlfn._xlws.FILTER(_xlfn.CHOOSECOLS(Purchase!B:M, 12, 3, 11), (Purchase!M:M >= TODAY()) * (Purchase!M:M <= TODAY()+14) * (Purchase!L:L > 0), "No upcoming bills"), 1, 1)} -> 46240 | T16: Bederco | U16: 18000
B17: 46198 | C17: 1 | S17: 46242 | T17: Bederco | U17: 2000
B18: 46199 | C18: 2 | P18: Product Name
B19: 46200 | C19: 7 | P19: P1
B20: 46201 | C20: 55 | P20: P2
B21: 46202 | C21: 1 | P21: P3
B22: 46203 | C22: 2 | P22: P4
B23: 46204 | C23: 3 | P23: P5
B24: 46205 | C24: 1 | P24: P6
B25: (blank) | C25: 52 | P25: P1 - P6
B26: Grand Total | C26: 185 | P26: P1 - P4
P27: P7
P28: P8
P29: P9
P30: P10
P31: P11
P32: P12
P33: P13
P34: P14
P35: P15
P36: P16
P37: P17
P38: P18
... P41: Grand Total
D42: Reorder Status | E42: Count of Reorder Status
D43: (blank)
D44: In Stock | E44: 1
D45: Adjustments (+) | E45: 1
D46: 0 | E46: 21
...

Sheet Product_Master
J1: Find product | K1: Quantity on Hand | M1: Reorder Status
C2: INVENTORY | J2: P1 | K2: =_xlfn.XLOOKUP(J2, $E$5:$E$996, $O$5:$O$996, "-") -> 43 | M2: =_xlfn.XLOOKUP(J2, $E$5:$E$996, $Q$5:$Q$996, "-") -> In Stock
B4: S/N | C4: SKU | D4: Parent SKU | E4: Product Name | F4: Category | G4: Pack Quantity | H4: Unit Cost | I4: Unit Price | J4: Initial Stock | K4: Total Received | L4: Total Sold | M4: Adjustments (+) | N4: Adjustments (-) | O4: On Hand | P4: Reorder Point | Q4: Reorder Status | R4: Margin | S4: Profit | T4: Expiration Date | U4: Inventory Value
B5: 1 | C5: SKU-001 | D5: =MID(LEFT(Product_Master[[#This Row],[SKU]], 7), FIND("-", Product_Master[[#This Row],[SKU]]) - 3, LEN(Product_Master[[#This Row],[SKU]])) -> SKU-001 | E5: P1 | F5: Beverage | G5: 1 | H5: =_xlfn.XLOOKUP(D5, Purchase!E:E, Purchase!I:I, 0, 0, -1) *Product_Master[[#This Row],[Pack Quantity]] -> 2000 | I5: 3000 | J5: 50 | K5: =SUMIF(Purchase!E:E, C5, Purchase!H:H) -> 10 | L5: =SUMIFS(Sales!H:H, Sales!E:E, Product_Master[[#This Row],[SKU]]) -> 14 | M5: =SUMIFS(Adjustments!C:C, Adjustments!A:A, Product_Master[[#This Row],[SKU]], Adjustments!D:D, "Adjustment - Add") -> 0 | N5: {=SUM(SUMIFS(Adjustments!C:C, Adjustments!A:A, Product_Master[[#This Row],[SKU]], Adjustments!D:D, {"Scrap","Adjustment - Subtract"}))} -> 3 | O5: =J5 + K5 - L5 + Product_Master[[#This Row],[Adjustments (+)]] - Product_Master[[#This Row],[Adjustments (-)]] -> 43 | P5: 3 | Q5: =IF(G5>1, "In Stock", IF(O5=0, "Out of Stock", IF(O5<=P5, "Low Stock", "In Stock"))) -> In Stock | R5: =IF(OR(ISBLANK(I5), I5=0), "-", (I5 - H5) / I5) -> 0.33333333 | S5: =IF(OR(ISBLANK(H5), ISBLANK(I5)), "-", I5 - H5) -> 1000 | T5: 47290 | U5: =Product_Master[[#This Row],[Unit Cost]]*Product_Master[[#This Row],[On Hand]] -> 86000
B6: 2 | C6: SKU-001-P6 | D6: =MID(LEFT(Product_Master[[#This Row],[SKU]], 7), FIND("-", Product_Master[[#This Row],[SKU]]) - 3, LEN(Product_Master[[#This Row],[SKU]])) -> SKU-001 | E6: P1 - P6 | F6: Beverage | G6: 6 | H6: =_xlfn.XLOOKUP(D6, Purchase!E:E, Purchase!I:I, 0, 0, -1) *Product_Master[[#This Row],[Pack Quantity]] -> 12000 | I6: 15000 | J6: 0 | K6: =SUMIF(Purchase!E:E, C6, Purchase!H:H) -> 0 | L6: =SUMIFS(Sales!H:H, Sales!E:E, Product_Master[[#This Row],[SKU]]) -> 0 | M6: =SUMIFS(Adjustments!C:C, Adjustments!A:A, Product_Master[[#This Row],[SKU]], Adjustments!D:D, "Adjustment - Add") -> 0 | N6: {=SUM(SUMIFS(Adjustments!C:C, Adjustments!A:A, Product_Master[[#This Row],[SKU]], Adjustments!D:D, {"Scrap","Adjustment - Subtract"}))} -> 0 | O6: =J6 + K6 - L6 + Product_Master[[#This Row],[Adjustments (+)]] - Product_Master[[#This Row],[Adjustments (-)]] -> 0 | P6: 0 | Q6: =IF(G6>1, "In Stock", IF(O6=0, "Out of Stock", IF(O6<=P6, "Low Stock", "In Stock"))) -> In Stock | R6: =IF(OR(ISBLANK(I6), I6=0), "-", (I6 - H6) / I6) -> 0.2 | S6: =IF(OR(ISBLANK(H6), ISBLANK(I6)), "-", I6 - H6) -> 3000 | U6: =Product_Master[[#This Row],[Unit Cost]]*Product_Master[[#This Row],[On Hand]] -> 0
B7: 3 | C7: SKU-001-P4 | D7: =MID(LEFT(Product_Master[[#This Row],[SKU]], 7), FIND("-", Product_Master[[#This Row],[SKU]]) - 3, LEN(Product_Master[[#This Row],[SKU]])) -> SKU-001 | E7: P1 - P4 | F7: Beverage | G7: 4 | H7: =_xlfn.XLOOKUP(D7, Purchase!E:E, Purchase!I:I, 0, 0, -1) *Product_Master[[#This Row],[Pack Quantity]] -> 8000 | I7: 11000 | J7: 0 | K7: =SUMIF(Purchase!E:E, C7, Purchase!H:H) -> 0 | L7: =SUMIFS(Sales!H:H, Sales!E:E, Product_Master[[#This Row],[SKU]]) -> 0 | M7: =SUMIFS(Adjustments!C:C, Adjustments!A:A, Product_Master[[#This Row],[SKU]], Adjustments!D:D, "Adjustment - Add") -> 0 | N7: {=SUM(SUMIFS(Adjustments!C:C, Adjustments!A:A, Product_Master[[#This Row],[SKU]], Adjustments!D:D, {"Scrap","Adjustment - Subtract"}))} -> 0 | O7: =J7 + K7 - L7 + Product_Master[[#This Row],[Adjustments (+)]] - Product_Master[[#This Row],[Adjustments (-)]] -> 0 | P7: 0 | Q7: =IF(G7>1, "In Stock", IF(O7=0, "Out of Stock", IF(O7<=P7, "Low Stock", "In Stock"))) -> In Stock | R7: =IF(OR(ISBLANK(I7), I7=0), "-", (I7 - H7) / I7) -> 0.27272727 | S7: =IF(OR(ISBLANK(H7), ISBLANK(I7)), "-", I7 - H7) -> 3000 | U7: =Product_Master[[#This Row],[Unit Cost]]*Product_Master[[#This Row],[On Hand]] -> 0
B8: 4 | C8: SKU-002 | D8: =MID(LEFT(Product_Master[[#This Row],[SKU]], 7), FIND("-", Product_Master[[#This Row],[SKU]]) - 3, LEN(Product_Master[[#This Row],[SKU]])) -> SKU-002 | E8: P2 | F8: Stationary | G8: 1 | H8: =_xlfn.XLOOKUP(D8, Purchase!E:E, Purchase!I:I, 0, 0, -1) *Product_Master[[#This Row],[Pack Quantity]] -> 1200 | I8: 1900 | J8: 50 | K8: =SUMIF(Purchase!E:E, C8, Purchase!H:H) -> 75 | L8: =SUMIFS(Sales!H:H, Sales!E:E, Product_Master[[#This Row],[SKU]]) -> 13 | M8: =SUMIFS(Adjustments!C:C, Adjustments!A:A, Product_Master[[#This Row],[SKU]], Adjustments!D:D, "Adjustment - Add") -> 0 | N8: {=SUM(SUMIFS(Adjustments!C:C, Adjustments!A:A, Product_Master[[#This Row],[SKU]], Adjustments!D:D, {"Scrap","Adjustment - Subtract"}))} -> 0 | O8: =J8 + K8 - L8 + Product_Master[[#This Row],[Adjustments (+)]] - Product_Master[[#This Row],[Adjustments (-)]] -> 112 | P8: 38 | Q8: =IF(G8>1, "In Stock", IF(O8=0, "Out of Stock", IF(O8<=P8, "Low Stock", "In Stock"))) -> In Stock | R8: =IF(OR(ISBLANK(I8), I8=0), "-", (I8 - H8) / I8) -> 0.36842105 | S8: =IF(OR(ISBLANK(H8), ISBLANK(I8)), "-", I8 - H8) -> 700 | T8: 46508 | U8: =Product_Master[[#This Row],[Unit Cost]]*Product_Master[[#This Row],[On Hand]] -> 134400
B9: 5 | C9: SKU-003 | D9: =MID(LEFT(Product_Master[[#This Row],[SKU]], 7), FIND("-", Product_Master[[#This Row],[SKU]]) - 3, LEN(Product_Master[[#This Row],[SKU]])) -> SKU-003 | E9: P3 | F9: Household | G9: 1 | H9: =_xlfn.XLOOKUP(D9, Purchase!E:E, Purchase!I:I, 0, 0, -1) *Product_Master[[#This Row],[Pack Quantity]] -> 500 | I9: 750 | J9: 50 | K9: =SUMIF(Purchase!E:E, C9, Purchase!H:H) -> 24 | L9: =SUMIFS(Sales!H:H, Sales!E:E, Product_Master[[#This Row],[SKU]]) -> 6 | M9: =SUMIFS(Adjustments!C:C, Adjustments!A:A, Product_Master[[#This Row],[SKU]], Adjustments!D:D, "Adjustment - Add") -> 1 | N9: {=SUM(SUMIFS(Adjustments!C:C, Adjustments!A:A, Product_Master[[#This Row],[SKU]], Adjustments!D:D, {"Scrap","Adjustment - Subtract"}))} -> 0 | O9: =J9 + K9 - L9 + Product_Master[[#This Row],[Adjustments (+)]] - Product_Master[[#This Row],[Adjustments (-)]] -> 69 | P9: 7 | Q9: =IF(G9>1, "In Stock", IF(O9=0, "Out of Stock", IF(O9<=P9, "Low Stock", "In Stock"))) -> In Stock | R9: =IF(OR(ISBLANK(I9), I9=0), "-", (I9 - H9) / I9) -> 0.33333333 | S9: =IF(OR(ISBLANK(H9), ISBLANK(I9)), "-", I9 - H9) -> 250 | T9: 46236 | U9: =Product_Master[[#This Row],[Unit Cost]]*Product_Master[[#This Row],[On Hand]] -> 34500
B10: 6 | C10: SKU-004 | D10: =MID(LEFT(Product_Master[[#This Row],[SKU]], 7), FIND("-", Product_Master[[#This Row],[SKU]]) - 3, LEN(Product_Master[[#This Row],[SKU]])) -> SKU-004 | E10: P4 | F10: Sanitary | G10: 1 | H10: =_xlfn.XLOOKUP(D10, Purchase!E:E, Purchase!I:I, 0, 0, -1) *Product_Master[[#This Row],[Pack Quantity]] -> 4000 | I10: 5500 | J10: 50 | K10: =SUMIF(Purchase!E:E, C10, Purchase!H:H) -> 48 | L10: =SUMIFS(Sales!H:H, Sales!E:E, Product_Master[[#This Row],[SKU]]) -> 17 | M10: =SUMIFS(Adjustments!C:C, Adjustments!A:A, Product_Master[[#This Row],[SKU]], Adjustments!D:D, "Adjustment - Add") -> 0 | N10: {=SUM(SUMIFS(Adjustments!C:C, Adjustments!A:A, Product_Master[[#This Row],[SKU]], Adjustments!D:D, {"Scrap","Adjustment - Subtract"}))} -> 0 | O10: =J10 + K10 - L10 + Product_Master[[#This Row],[Adjustments (+)]] - Product_Master[[#This Row],[Adjustments (-)]] -> 81 | P10: 11 | Q10: =IF(G10>1, "In Stock", IF(O10=0, "Out of Stock", IF(O10<=P10, "Low Stock", "In Stock"))) -> In Stock | R10: =IF(OR(ISBLANK(I10), I10=0), "-", (I10 - H10) / I10) -> 0.27272727 | S10: =IF(OR(ISBLANK(H10), ISBLANK(I10)), "-", I10 - H10) -> 1500 | T10: 46205 | U10: =Product_Master[[#This Row],[Unit Cost]]*Product_Master[[#This Row],[On Hand]] -> 324000
B11: 7 | C11: SKU-005 | D11: =MID(LEFT(Product_Master[[#This Row],[SKU]], 7), FIND("-", Product_Master[[#This Row],[SKU]]) - 3, LEN(Product_Master[[#This Row],[SKU]])) -> SKU-005 | E11: P5 | F11: Toiletry | G11: 1 | H11: =_xlfn.XLOOKUP(D11, Purchase!E:E, Purchase!I:I, 0, 0, -1) *Product_Master[[#This Row],[Pack Quantity]] -> 3500 | I11: 4500 | J11: 50 | K11: =SUMIF(Purchase!E:E, C11, Purchase!H:H) -> 12 | L11: =SUMIFS(Sales!H:H, Sales!E:E, Product_Master[[#This Row],[SKU]]) -> 1 | M11: =SUMIFS(Adjustments!C:C, Adjustments!A:A, Product_Master[[#This Row],[SKU]], Adjustments!D:D, "Adjustment - Add") -> 0 | N11: {=SUM(SUMIFS(Adjustments!C:C, Adjustments!A:A, Product_Master[[#This Row],[SKU]], Adjustments!D:D, {"Scrap","Adjustment - Subtract"}))} -> 0 | O11: =J11 + K11 - L11 + Product_Master[[#This Row],[Adjustments (+)]] - Product_Master[[#This Row],[Adjustments (-)]] -> 61 | P11: 7 | Q11: =IF(G11>1, "In Stock", IF(O11=0, "Out of Stock", IF(O11<=P11, "Low Stock", "In Stock"))) -> In Stock | R11: =IF(OR(ISBLANK(I11), I11=0), "-", (I11 - H11) / I11) -> 0.22222222 | S11: =IF(OR(ISBLANK(H11), ISBLANK(I11)), "-", I11 - H11) -> 1000 | T11: 46179 | U11: =Product_Master[[#This Row],[Unit Cost]]*Product_Master[[#This Row],[On Hand]] -> 213500
B12: 8 | C12: SKU-006 | D12: =MID(LEFT(Product_Master[[#This Row],[SKU]], 7), FIND("-", Product_Master[[#This Row],[SKU]]) - 3, LEN(Product_Master[[#This Row],[SKU]])) -> SKU-006 | E12: P6 | F12: Pasteries | G12: 1 | H12: =_xlfn.XLOOKUP(D12, Purchase!E:E, Purchase!I:I, 0, 0, -1) *Product_Master[[#This Row],[Pack Quantity]] -> 5900 | I12: 7000 | J12: 50 | K12: =SUMIF(Purchase!E:E, C12, Purchase!H:H) -> 20 | L12: =SUMIFS(Sales!H:H, Sales!E:E, Product_Master[[#This Row],[SKU]]) -> 12 | M12: =SUMIFS(Adjustments!C:C, Adjustments!A:A, Product_Master[[#This Row],[SKU]], Adjustments!D:D, "Adjustment - Add") -> 0 | N12: {=SUM(SUMIFS(Adjustments!C:C, Adjustments!A:A, Product_Master[[#This Row],[SKU]], Adjustments!D:D, {"Scrap","Adjustment - Subtract"}))} -> 0 | O12: =J12 + K12 - L12 + Product_Master[[#This Row],[Adjustments (+)]] - Product_Master[[#This Row],[Adjustments (-)]] -> 58 | P12: 3 | Q12: =IF(G12>1, "In Stock", IF(O12=0, "Out of Stock", IF(O12<=P12, "Low Stock", "In Stock"))) -> In Stock | R12: =IF(OR(ISBLANK(I12), I12=0), "-", (I12 - H12) / I12) -> 0.15714286 | S12: =IF(OR(ISBLANK(H12), ISBLANK(I12)), "-", I12 - H12) -> 1100 | T12: 47699 | U12: =Product_Master[[#This Row],[Unit Cost]]*Product_Master[[#This Row],[On Hand]] -> 342200
B13: 9 | C13: SKU-007 | D13: =MID(LEFT(Product_Master[[#This Row],[SKU]], 7), FIND("-", Product_Master[[#This Row],[SKU]]) - 3, LEN(Product_Master[[#This Row],[SKU]])) -> SKU-007 | E13: P7 | F13: Household | G13: 1 | H13: =_xlfn.XLOOKUP(D13, Purchase!E:E, Purchase!I:I, 0, 0, -1) *Product_Master[[#This Row],[Pack Quantity]] -> 5000 | I13: 6200 | J13: 50 | K13: =SUMIF(Purchase!E:E, C13, Purchase!H:H) -> 90 | L13: =SUMIFS(Sales!H:H, Sales!E:E, Product_Master[[#This Row],[SKU]]) -> 0 | M13: =SUMIFS(Adjustments!C:C, Adjustments!A:A, Product_Master[[#This Row],[SKU]], Adjustments!D:D, "Adjustment - Add") -> 0 | N13: {=SUM(SUMIFS(Adjustments!C:C, Adjustments!A:A, Product_Master[[#This Row],[SKU]], Adjustments!D:D, {"Scrap","Adjustment - Subtract"}))} -> 0 | O13: =J13 + K13 - L13 + Product_Master[[#This Row],[Adjustments (+)]] - Product_Master[[#This Row],[Adjustments (-)]] -> 140 | P13: 8 | Q13: =IF(G13>1, "In Stock", IF(O13=0, "Out of Stock", IF(O13<=P13, "Low Stock", "In Stock"))) -> In Stock | R13: =IF(OR(ISBLANK(I13), I13=0), "-", (I13 - H13) / I13) -> 0.19354839 | S13: =IF(OR(ISBLANK(H13), ISBLANK(I13)), "-", I13 - H13) -> 1200 | T13: 46512 | U13: =Product_Master[[#This Row],[Unit Cost]]*Product_Master[[#This Row],[On Hand]] -> 700000
B14: 10 | C14: SKU-008 | D14: =MID(LEFT(Product_Master[[#This Row],[SKU]], 7), FIND("-", Product_Master[[#This Row],[SKU]]) - 3, LEN(Product_Master[[#This Row],[SKU]])) -> SKU-008 | E14: P8 | F14: Stationary | G14: 1 | H14: =_xlfn.XLOOKUP(D14, Purchase!E:E, Purchase!I:I, 0, 0, -1) *Product_Master[[#This Row],[Pack Quantity]] -> 900 | I14: 1200 | J14: 50 | K14: =SUMIF(Purchase!E:E, C14, Purchase!H:H) -> 12 | L14: =SUMIFS(Sales!H:H, Sales!E:E, Product_Master[[#This Row],[SKU]]) -> 0 | M14: =SUMIFS(Adjustments!C:C, Adjustments!A:A, Product_Master[[#This Row],[SKU]], Adjustments!D:D, "Adjustment - Add") -> 0 | N14: {=SUM(SUMIFS(Adjustments!C:C, Adjustments!A:A, Product_Master[[#This Row],[SKU]], Adjustments!D:D, {"Scrap","Adjustment - Subtract"}))} -> 0 | O14: =J14 + K14 - L14 + Product_Master[[#This Row],[Adjustments (+)]] - Product_Master[[#This Row],[Adjustments (-)]] -> 62 | P14: 4 | Q14: =IF(G14>1, "In Stock", IF(O14=0, "Out of Stock", IF(O14<=P14, "Low Stock", "In Stock"))) -> In Stock | R14: =IF(OR(ISBLANK(I14), I14=0), "-", (I14 - H14) / I14) -> 0.25 | S14: =IF(OR(ISBLANK(H14), ISBLANK(I14)), "-", I14 - H14) -> 300 | T14: 46191 | U14: =Product_Master[[#This Row],[Unit Cost]]*Product_Master[[#This Row],[On Hand]] -> 55800
B15: 11 | C15: SKU-009 | D15: =MID(LEFT(Product_Master[[#This Row],[SKU]], 7), FIND("-", Product_Master[[#This Row],[SKU]]) - 3, LEN(Product_Master[[#This Row],[SKU]])) -> SKU-009 | E15: P9 | F15: Beverage | G15: 1 | H15: =_xlfn.XLOOKUP(D15, Purchase!E:E, Purchase!I:I, 0, 0, -1) *Product_Master[[#This Row],[Pack Quantity]] -> 540 | I15: 900 | J15: 50 | K15: =SUMIF(Purchase!E:E, C15, Purchase!H:H) -> 48 | L15: =SUMIFS(Sales!H:H, Sales!E:E, Product_Master[[#This Row],[SKU]]) -> 0 | M15: =SUMIFS(Adjustments!C:C, Adjustments!A:A, Product_Master[[#This Row],[SKU]], Adjustments!D:D, "Adjustment - Add") -> 0 | N15: {=SUM(SUMIFS(Adjustments!C:C, Adjustments!A:A, Product_Master[[#This Row],[SKU]], Adjustments!D:D, {"Scrap","Adjustment - Subtract"}))} -> 0 | O15: =J15 + K15 - L15 + Product_Master[[#This Row],[Adjustments (+)]] - Product_Master[[#This Row],[Adjustments (-)]] -> 98 | P15: 7 | Q15: =IF(G15>1, "In Stock", IF(O15=0, "Out of Stock", IF(O15<=P15, "Low Stock", "In Stock"))) -> In Stock | R15: =IF(OR(ISBLANK(I15), I15=0), "-", (I15 - H15) / I15) -> 0.4 | S15: =IF(OR(ISBLANK(H15), ISBLANK(I15)), "-", I15 - H15) -> 360 | T15: 46192 | U15: =Product_Master[[#This Row],[Unit Cost]]*Product_Master[[#This Row],[On Hand]] -> 52920
B16: 12 | C16: SKU-010 | D16: =MID(LEFT(Product_Master[[#This Row],[SKU]], 7), FIND("-", Product_Master[[#This Row],[SKU]]) - 3, LEN(Product_Master[[#This Row],[SKU]])) -> SKU-010 | E16: P10 | F16: Sanitary | G16: 1 | H16: =_xlfn.XLOOKUP(D16, Purchase!E:E, Purchase!I:I, 0, 0, -1) *Product_Master[[#This Row],[Pack Quantity]] -> 9700 | I16: 12000 | J16: 50 | K16: =SUMIF(Purchase!E:E, C16, Purchase!H:H) -> 50 | L16: =SUMIFS(Sales!H:H, Sales!E:E, Product_Master[[#This Row],[SKU]]) -> 0 | M16: =SUMIFS(Adjustments!C:C, Adjustments!A:A, Product_Master[[#This Row],[SKU]], Adjustments!D:D, "Adjustment - Add") -> 0 | N16: {=SUM(SUMIFS(Adjustments!C:C, Adjustments!A:A, Product_Master[[#This Row],[SKU]], Adjustments!D:D, {"Scrap","Adjustment - Subtract"}))} -> 0 | O16: =J16 + K16 - L16 + Product_Master[[#This Row],[Adjustments (+)]] - Product_Master[[#This Row],[Adjustments (-)]] -> 100 | P16: 6 | Q16: =IF(G16>1, "In Stock", IF(O16=0, "Out of Stock", IF(O16<=P16, "Low Stock", "In Stock"))) -> In Stock | R16: =IF(OR(ISBLANK(I16), I16=0), "-", (I16 - H16) / I16) -> 0.19166667 | S16: =IF(OR(ISBLANK(H16), ISBLANK(I16)), "-", I16 - H16) -> 2300 | T16: 46832 | U16: =Product_Master[[#This Row],[Unit Cost]]*Product_Master[[#This Row],[On Hand]] -> 970000
B17: 13 | C17: SKU-011 | D17: =MID(LEFT(Product_Master[[#This Row],[SKU]], 7), FIND("-", Product_Master[[#This Row],[SKU]]) - 3, LEN(Product_Master[[#This Row],[SKU]])) -> SKU-011 | E17: P11 | F17: Pasteries | G17: 1 | H17: =_xlfn.XLOOKUP(D17, Purchase!E:E, Purchase!I:I, 0, 0, -1) *Product_Master[[#This Row],[Pack Quantity]] -> 2000 | I17: 3800 | J17: 50 | K17: =SUMIF(Purchase!E:E, C17, Purchase!H:H) -> 72 | L17: =SUMIFS(Sales!H:H, Sales!E:E, Product_Master[[#This Row],[SKU]]) -> 0 | M17: =SUMIFS(Adjustments!C:C, Adjustments!A:A, Product_Master[[#This Row],[SKU]], Adjustments!D:D, "Adjustment - Add") -> 0 | N17: {=SUM(SUMIFS(Adjustments!C:C, Adjustments!A:A, Product_Master[[#This Row],[SKU]], Adjustments!D:D, {"Scrap","Adjustment - Subtract"}))} -> 0 | O17: =J17 + K17 - L17 + Product_Master[[#This Row],[Adjustments (+)]] - Product_Master[[#This Row],[Adjustments (-)]] -> 122 | P17: 9 | Q17: =IF(G17>1, "In Stock", IF(O17=0, "Out of Stock", IF(O17<=P17, "Low Stock", "In Stock"))) -> In Stock | R17: =IF(OR(ISBLANK(I17), I17=0), "-", (I17 - H17) / I17) -> 0.47368421 | S17: =IF(OR(ISBLANK(H17), ISBLANK(I17)), "-", I17 - H17) -> 1800 | T17: 47584 | U17: =Product_Master[[#This Row],[Unit Cost]]*Product_Master[[#This Row],[On Hand]] -> 244000
B18: 14 | C18: SKU-012 | D18: =MID(LEFT(Product_Master[[#This Row],[SKU]], 7), FIND("-", Product_Master[[#This Row],[SKU]]) - 3, LEN(Product_Master[[#This Row],[SKU]])) -> SKU-012 | E18: P12 | F18: Stationary | G18: 1 | H18: =_xlfn.XLOOKUP(D18, Purchase!E:E, Purchase!I:I, 0, 0, -1) *Product_Master[[#This Row],[Pack Quantity]] -> 4400 | I18: 6000 | J18: 50 | K18: =SUMIF(Purchase!E:E, C18, Purchase!H:H) -> 30 | L18: =SUMIFS(Sales!H:H, Sales!E:E, Product_Master[[#This Row],[SKU]]) -> 0 | M18: =SUMIFS(Adjustments!C:C, Adjustments!A:A, Product_Master[[#This Row],[SKU]], Adjustments!D:D, "Adjustment - Add") -> 0 | N18: {=SUM(SUMIFS(Adjustments!C:C, Adjustments!A:A, Product_Master[[#This Row],[SKU]], Adjustments!D:D, {"Scrap","Adjustment - Subtract"}))} -> 0 | O18: =J18 + K18 - L18 + Product_Master[[#This Row],[Adjustments (+)]] - Product_Master[[#This Row],[Adjustments (-)]] -> 80 | P18: 4 | Q18: =IF(G18>1, "In Stock", IF(O18=0, "Out of Stock", IF(O18<=P18, "Low Stock", "In Stock"))) -> In Stock | R18: =IF(OR(ISBLANK(I18), I18=0), "-", (I18 - H18) / I18) -> 0.26666667 | S18: =IF(OR(ISBLANK(H18), ISBLANK(I18)), "-", I18 - H18) -> 1600 | T18: 46764 | U18: =Product_Master[[#This Row],[Unit Cost]]*Product_Master[[#This Row],[On Hand]] -> 352000
B19: 15 | C19: SKU-013 | D19: =MID(LEFT(Product_Master[[#This Row],[SKU]], 7), FIND("-", Product_Master[[#This Row],[SKU]]) - 3, LEN(Product_Master[[#This Row],[SKU]])) -> SKU-013 | E19: P13 | F19: Beverage | G19: 1 | H19: =_xlfn.XLOOKUP(D19, Purchase!E:E, Purchase!I:I, 0, 0, -1) *Product_Master[[#This Row],[Pack Quantity]] -> 650 | I19: 1000 | J19: 50 | K19: =SUMIF(Purchase!E:E, C19, Purchase!H:H) -> 12 | L19: =SUMIFS(Sales!H:H, Sales!E:E, Product_Master[[#This Row],[SKU]]) -> 62 | M19: =SUMIFS(Adjustments!C:C, Adjustments!A:A, Product_Master[[#This Row],[SKU]], Adjustments!D:D, "Adjustment - Add") -> 0 | N19: {=SUM(SUMIFS(Adjustments!C:C, Adjustments!A:A, Product_Master[[#This Row],[SKU]], Adjustments!D:D, {"Scrap","Adjustment - Subtract"}))} -> 0 | O19: =J19 + K19 - L19 + Product_Master[[#This Row],[Adjustments (+)]] - Product_Master[[#This Row],[Adjustments (-)]] -> 0 | P19: 13 | Q19: =IF(G19>1, "In Stock", IF(O19=0, "Out of Stock", IF(O19<=P19, "Low Stock", "In Stock"))) -> Out of Stock | R19: =IF(OR(ISBLANK(I19), I19=0), "-", (I19 - H19) / I19) -> 0.35 | S19: =IF(OR(ISBLANK(H19), ISBLANK(I19)), "-", I19 - H19) -> 350 | T19: 46210 | U19: =Product_Master[[#This Row],[Unit Cost]]*Product_Master[[#This Row],[On Hand]] -> 0
... B26: 22 | C26: SKU-019-20 | D26: =MID(LEFT(Product_Master[[#This Row],[SKU]], 7), FIND("-", Product_Master[[#This Row],[SKU]]) - 3, LEN(Product_Master[[#This Row],[SKU]])) -> SKU-019 | E26: P20 | F26: Household | G26: 20 | H26: =_xlfn.XLOOKUP(D26, Purchase!E:E, Purchase!I:I, 0, 0, -1) *Product_Master[[#This Row],[Pack Quantity]] -> 100000 | I26: 150000 | J26: 0 | K26: =SUMIF(Purchase!E:E, C26, Purchase!H:H) -> 0 | L26: =SUMIFS(Sales!H:H, Sales!E:E, Product_Master[[#This Row],[SKU]]) -> 0 | M26: =SUMIFS(Adjustments!C:C, Adjustments!A:A, Product_Master[[#This Row],[SKU]], Adjustments!D:D, "Adjustment - Add") -> 0 | N26: {=SUM(SUMIFS(Adjustments!C:C, Adjustments!A:A, Product_Master[[#This Row],[SKU]], Adjustments!D:D, {"Scrap","Adjustment - Subtract"}))} -> 0 | O26: =J26 + K26 - L26 + Product_Master[[#This Row],[Adjustments (+)]] - Product_Master[[#This Row],[Adjustments (-)]] -> 0 | P26: 0 | Q26: =IF(G26>1, "In Stock", IF(O26=0, "Out of Stock", IF(O26<=P26, "Low Stock", "In Stock"))) -> In Stock | R26: =IF(OR(ISBLANK(I26), I26=0), "-", (I26 - H26) / I26) -> 0.33333333 | S26: =IF(OR(ISBLANK(H26), ISBLANK(I26)), "-", I26 - H26) -> 50000 | T26: 46910 | U26: =Product_Master[[#This Row],[Unit Cost]]*Product_Master[[#This Row],[On Hand]] -> 0

Sheet Purchase
C1: STOCK-IN
B2: Date | C2: Transaction ID | D2: Supplier | E2: SKU | F2: Product Name | G2: Category | H2: Quantity | I2: Unit Cost | J2: Total purcahse | K2: Paid | L2: Balance to Pay | M2: Due Date | N2: Recieved by
B3: 46179 | C3: P00001 | D3: Bederco | E3: SKU-001 | F3: =_xlfn.XLOOKUP(E3, Product_Master[SKU], Product_Master[Product Name], "Unknown SKU") -> P1 | G3: =_xlfn.XLOOKUP(E3, Product_Master[SKU], Product_Master[Category], "Unknown SKU") -> Beverage | H3: 10 | I3: 2000 | J3: =Table8[[#This Row],[Unit Cost]]*Table8[[#This Row],[Quantity]] -> 20000 | K3: 2000 | L3: =Table8[[#This Row],[Total purcahse]]-Table8[[#This Row],[Paid]] -> 18000 | M3: 46240 | N3: Mary
B4: 46179 | C4: P00002 | D4: Bederco | E4: SKU-002 | F4: =_xlfn.XLOOKUP(E4, Product_Master[SKU], Product_Master[Product Name], "Unknown SKU") -> P2 | G4: =_xlfn.XLOOKUP(E4, Product_Master[SKU], Product_Master[Category], "Unknown SKU") -> Stationary | H4: 15 | I4: 1400 | J4: =Table8[[#This Row],[Unit Cost]]*Table8[[#This Row],[Quantity]] -> 21000 | K4: 21000 | L4: =Table8[[#This Row],[Total purcahse]]-Table8[[#This Row],[Paid]] -> 0 | N4: Mary
B5: 46179 | C5: P00003 | D5: Bederco | E5: SKU-003 | F5: =_xlfn.XLOOKUP(E5, Product_Master[SKU], Product_Master[Product Name], "Unknown SKU") -> P3 | G5: =_xlfn.XLOOKUP(E5, Product_Master[SKU], Product_Master[Category], "Unknown SKU") -> Household | H5: 24 | I5: 500 | J5: =Table8[[#This Row],[Unit Cost]]*Table8[[#This Row],[Quantity]] -> 12000 | K5: 10000 | L5: =Table8[[#This Row],[Total purcahse]]-Table8[[#This Row],[Paid]] -> 2000 | M5: 46242 | N5: Mary
B6: 46179 | C6: P00004 | D6: Bederco | E6: SKU-008 | F6: =_xlfn.XLOOKUP(E6, Product_Master[SKU], Product_Master[Product Name], "Unknown SKU") -> P8 | G6: =_xlfn.XLOOKUP(E6, Product_Master[SKU], Product_Master[Category], "Unknown SKU") -> Stationary | H6: 12 | I6: 900 | J6: =Table8[[#This Row],[Unit Cost]]*Table8[[#This Row],[Quantity]] -> 10800 | K6: 10800 | L6: =Table8[[#This Row],[Total purcahse]]-Table8[[#This Row],[Paid]] -> 0 | N6: Mary
B7: 46179 | C7: P00005 | D7: Bederco | E7: SKU-011 | F7: =_xlfn.XLOOKUP(E7, Product_Master[SKU], Product_Master[Product Name], "Unknown SKU") -> P11 | G7: =_xlfn.XLOOKUP(E7, Product_Master[SKU], Product_Master[Category], "Unknown SKU") -> Pasteries | H7: 36 | I7: 2500 | J7: =Table8[[#This Row],[Unit Cost]]*Table8[[#This Row],[Quantity]] -> 90000 | K7: 90000 | L7: =Table8[[#This Row],[Total purcahse]]-Table8[[#This Row],[Paid]] -> 0 | N7: Mary
B8: 46179 | C8: P00006 | D8: King James | E8: SKU-007 | F8: =_xlfn.XLOOKUP(E8, Product_Master[SKU], Product_Master[Product Name], "Unknown SKU") -> P7 | G8: =_xlfn.XLOOKUP(E8, Product_Master[SKU], Product_Master[Category], "Unknown SKU") -> Household | H8: 90 | I8: 5000 | J8: =Table8[[#This Row],[Unit Cost]]*Table8[[#This Row],[Quantity]] -> 450000 | L8: =Table8[[#This Row],[Total purcahse]]-Table8[[#This Row],[Paid]] -> 450000 | M8: 46234 | N8: Mary
B9: 46179 | C9: P00007 | D9: King James | E9: SKU-004 | F9: =_xlfn.XLOOKUP(E9, Product_Master[SKU], Product_Master[Product Name], "Unknown SKU") -> P4 | G9: =_xlfn.XLOOKUP(E9, Product_Master[SKU], Product_Master[Category], "Unknown SKU") -> Sanitary | H9: 48 | I9: 4000 | J9: =Table8[[#This Row],[Unit Cost]]*Table8[[#This Row],[Quantity]] -> 192000 | K9: 96000 | L9: =Table8[[#This Row],[Total purcahse]]-Table8[[#This Row],[Paid]] -> 96000 | M9: 46210 | N9: Mary
B10: 46179 | C10: P00008 | D10: King James | E10: SKU-005 | F10: =_xlfn.XLOOKUP(E10, Product_Master[SKU], Product_Master[Product Name], "Unknown SKU") -> P5 | G10: =_xlfn.XLOOKUP(E10, Product_Master[SKU], Product_Master[Category], "Unknown SKU") -> Toiletry | H10: 12 | I10: 3500 | J10: =Table8[[#This Row],[Unit Cost]]*Table8[[#This Row],[Quantity]] -> 42000 | K10: 42000 | L10: =Table8[[#This Row],[Total purcahse]]-Table8[[#This Row],[Paid]] -> 0 | N10: Mary
B11: 46179 | C11: P00009 | D11: King James | E11: SKU-011 | F11: =_xlfn.XLOOKUP(E11, Product_Master[SKU], Product_Master[Product Name], "Unknown SKU") -> P11 | G11: =_xlfn.XLOOKUP(E11, Product_Master[SKU], Product_Master[Category], "Unknown SKU") -> Pasteries | H11: 36 | I11: 2000 | J11: =Table8[[#This Row],[Unit Cost]]*Table8[[#This Row],[Quantity]] -> 72000 | K11: 30000 | L11: =Table8[[#This Row],[Total purcahse]]-Table8[[#This Row],[Paid]] -> 42000 | M11: 46209 | N11: Mary
B12: 46179 | C12: P00010 | D12: King James | E12: SKU-015 | F12: =_xlfn.XLOOKUP(E12, Product_Master[SKU], Product_Master[Product Name], "Unknown SKU") -> P15 | G12: =_xlfn.XLOOKUP(E12, Product_Master[SKU], Product_Master[Category], "Unknown SKU") -> Stationary | H12: 80 | I12: 600 | J12: =Table8[[#This Row],[Unit Cost]]*Table8[[#This Row],[Quantity]] -> 48000 | K12: 48000 | L12: =Table8[[#This Row],[Total purcahse]]-Table8[[#This Row],[Paid]] -> 0 | N12: Mary
B13: 46179 | C13: P00011 | D13: King James | E13: SKU-018 | F13: =_xlfn.XLOOKUP(E13, Product_Master[SKU], Product_Master[Product Name], "Unknown SKU") -> P18 | G13: =_xlfn.XLOOKUP(E13, Product_Master[SKU], Product_Master[Category], "Unknown SKU") -> Toiletry | H13: 40 | I13: 6700 | J13: =Table8[[#This Row],[Unit Cost]]*Table8[[#This Row],[Quantity]] -> 268000 | K13: 10000 | L13: =Table8[[#This Row],[Total purcahse]]-Table8[[#This Row],[Paid]] -> 258000 | M13: 46264 | N13: Mary
B14: 46179 | C14: P00012 | D14: King James | E14: SKU-006 | F14: =_xlfn.XLOOKUP(E14, Product_Master[SKU], Product_Master[Product Name], "Unknown SKU") -> P6 | G14: =_xlfn.XLOOKUP(E14, Product_Master[SKU], Product_Master[Category], "Unknown SKU") -> Pasteries | H14: 20 | I14: 5900 | J14: =Table8[[#This Row],[Unit Cost]]*Table8[[#This Row],[Quantity]] -> 118000 | K14: 50000 | L14: =Table8[[#This Row],[Total purcahse]]-Table8[[#This Row],[Paid]] -> 68000 | M14: 46210 | N14: Mary
B15: 46180 | C15: P00013 | D15: Sujaco Empire | E15: SKU-002 | F15: =_xlfn.XLOOKUP(E15, Product_Master[SKU], Product_Master[Product Name], "Unknown SKU") -> P2 | G15: =_xlfn.XLOOKUP(E15, Product_Master[SKU], Product_Master[Category], "Unknown SKU") -> Stationary | H15: 60 | I15: 1200 | J15: =Table8[[#This Row],[Unit Cost]]*Table8[[#This Row],[Quantity]] -> 72000 | K15: 40000 | L15: =Table8[[#This Row],[Total purcahse]]-Table8[[#This Row],[Paid]] -> 32000 | M15: 46210 | N15: Mary
B16: 46180 | C16: P00014 | D16: Sujaco Empire | E16: SKU-009 | F16: =_xlfn.XLOOKUP(E16, Product_Master[SKU], Product_Master[Product Name], "Unknown SKU") -> P9 | G16: =_xlfn.XLOOKUP(E16, Product_Master[SKU], Product_Master[Category], "Unknown SKU") -> Beverage | H16: 48 | I16: 540 | J16: =Table8[[#This Row],[Unit Cost]]*Table8[[#This Row],[Quantity]] -> 25920 | K16: 25920 | L16: =Table8[[#This Row],[Total purcahse]]-Table8[[#This Row],[Paid]] -> 0 | N16: Mary
B17: 46180 | C17: P00015 | D17: Sujaco Empire | E17: SKU-010 | F17: =_xlfn.XLOOKUP(E17, Product_Master[SKU], Product_Master[Product Name], "Unknown SKU") -> P10 | G17: =_xlfn.XLOOKUP(E17, Product_Master[SKU], Product_Master[Category], "Unknown SKU") -> Sanitary | H17: 50 | I17: 9700 | J17: =Table8[[#This Row],[Unit Cost]]*Table8[[#This Row],[Quantity]] -> 485000 | K17: 15000 | L17: =Table8[[#This Row],[Total purcahse]]-Table8[[#This Row],[Paid]] -> 470000 | M17: 46271 | N17: Mary
B18: 46180 | C18: P00016 | D18: Sujaco Empire | E18: SKU-013 | F18: =_xlfn.XLOOKUP(E18, Product_Master[SKU], Product_Master[Product Name], "Unknown SKU") -> P13 | G18: =_xlfn.XLOOKUP(E18, Product_Master[SKU], Product_Master[Category], "Unknown SKU") -> Beverage | H18: 12 | I18: 650 | J18: =Table8[[#This Row],[Unit Cost]]*Table8[[#This Row],[Quantity]] -> 7800 | K18: 7800 | L18: =Table8[[#This Row],[Total purcahse]]-Table8[[#This Row],[Paid]] -> 0 | N18: Mary
B19: 46180 | C19: P00017 | D19: Mama didi Plaza | E19: SKU-016 | F19: =_xlfn.XLOOKUP(E19, Product_Master[SKU], Product_Master[Product Name], "Unknown SKU") -> P16 | G19: =_xlfn.XLOOKUP(E19, Product_Master[SKU], Product_Master[Category], "Unknown SKU") -> Pasteries | H19: 6 | I19: 4330 | J19: =Table8[[#This Row],[Unit Cost]]*Table8[[#This Row],[Quantity]] -> 25980 | K19: 25980 | L19: =Table8[[#This Row],[Total purcahse]]-Table8[[#This Row],[Paid]] -> 0 | N19: Mary
B20: 46180 | C20: P00018 | D20: Mama didi Plaza | E20: SKU-012 | F20: =_xlfn.XLOOKUP(E20, Product_Master[SKU], Product_Master[Product Name], "Unknown SKU") -> P12 | G20: =_xlfn.XLOOKUP(E20, Product_Master[SKU], Product_Master[Category], "Unknown SKU") -> Stationary | H20: 30 | I20: 4400 | J20: =Table8[[#This Row],[Unit Cost]]*Table8[[#This Row],[Quantity]] -> 132000 | K20: 10000 | L20: =Table8[[#This Row],[Total purcahse]]-Table8[[#This Row],[Paid]] -> 122000 | M20: 46285 | N20: Mary
B21: 46180 | C21: P00019 | D21: Mama didi Plaza | E21: SKU-014 | F21: =_xlfn.XLOOKUP(E21, Product_Master[SKU], Product_Master[Product Name], "Unknown SKU") -> P14 | G21: =_xlfn.XLOOKUP(E21, Product_Master[SKU], Product_Master[Category], "Unknown SKU") -> Toiletry | H21: 14 | I21: 260 | J21: =Table8[[#This Row],[Unit Cost]]*Table8[[#This Row],[Quantity]] -> 3640 | K21: 3640 | L21: =Table8[[#This Row],[Total purcahse]]-Table8[[#This Row],[Paid]] -> 0 | N21: Mary
B22: 46180 | C22: P00020 | D22: Mama didi Plaza | E22: SKU-017 | F22: =_xlfn.XLOOKUP(E22, Product_Master[SKU], Product_Master[Product Name], "Unknown SKU") -> P17 | G22: =_xlfn.XLOOKUP(E22, Product_Master[SKU], Product_Master[Category], "Unknown SKU") -> Sanitary | H22: 20 | I22: 700 | J22: =Table8[[#This Row],[Unit Cost]]*Table8[[#This Row],[Quantity]] -> 14000 | K22: 14000 | L22: =Table8[[#This Row],[Total purcahse]]-Table8[[#This Row],[Paid]] -> 0 | N22: Mary
B23: 46180 | C23: P00021 | D23: Mama didi Plaza | E23: SKU-019 | F23: =_xlfn.XLOOKUP(E23, Product_Master[SKU], Product_Master[Product Name], "Unknown SKU") -> P19 | G23: =_xlfn.XLOOKUP(E23, Product_Master[SKU], Product_Master[Category], "Unknown SKU") -> Household | H23: 10 | I23: 5000 | J23: =Table8[[#This Row],[Unit Cost]]*Table8[[#This Row],[Quantity]] -> 50000 | K23: 50000 | L23: =Table8[[#This Row],[Total purcahse]]-Table8[[#This Row],[Paid]] -> 0 | N23: Mary

Sheet Sales
C1: STOCK-OUT
B2: Date | C2: Transaction ID | D2: SKU | E2: Parent SKU | F2: Product Name | G2: Category | H2: Quantity | I2: Base Quantity | J2: Unit Price | K2: Total Revenue | L2: Customer | M2: Cashier | N2: POS | O2: Transfer | P2: Cash | Q2: Total Paid | R2: Outstanding | S2: Net Profit
B3: 46190 | C3: S00001 | D3: SKU-001 | E3: =_xlfn.XLOOKUP(D3, Product_Master[SKU], Product_Master[Parent SKU], "Unknown SKU") -> SKU-001 | F3: =_xlfn.XLOOKUP(D3, Product_Master[SKU], Product_Master[Product Name], "Unknown SKU") -> P1 | G3: =_xlfn.XLOOKUP(D3, Product_Master[SKU], Product_Master[Category], "Unknown SKU") -> Beverage | H3: 9 | I3: =Stock_Out_Log[[#This Row],[Quantity]] * _xlfn.XLOOKUP(Stock_Out_Log[[#This Row],[SKU]], Product_Master!C:C, Product_Master!G:G, 1) -> 9 | J3: =_xlfn.XLOOKUP(D3, Product_Master[SKU], Product_Master[Unit Price], 0) -> 3000 | K3: =H3 * J3 -> 27000 | M3: John | O3: 13000 | Q3: =Stock_Out_Log[[#This Row],[Cash]]+Stock_Out_Log[[#This Row],[Transfer]]+Stock_Out_Log[[#This Row],[POS]] -> 13000 | R3: =Stock_Out_Log[[#This Row],[Total Revenue]]-Stock_Out_Log[[#This Row],[Total Paid ]] -> 14000 | S3: =K3 - (H3 * _xlfn.XLOOKUP(D3, Product_Master!B:B, Product_Master!H:H, 0)) -> 27000
B4: 46190 | C4: S00002 | D4: SKU-001-P6 | E4: =_xlfn.XLOOKUP(D4, Product_Master[SKU], Product_Master[Parent SKU], "Unknown SKU") -> SKU-001 | F4: =_xlfn.XLOOKUP(D4, Product_Master[SKU], Product_Master[Product Name], "Unknown SKU") -> P1 - P6 | G4: =_xlfn.XLOOKUP(D4, Product_Master[SKU], Product_Master[Category], "Unknown SKU") -> Beverage | H4: 2 | I4: =Stock_Out_Log[[#This Row],[Quantity]] * _xlfn.XLOOKUP(Stock_Out_Log[[#This Row],[SKU]], Product_Master!C:C, Product_Master!G:G, 1) -> 12 | J4: =_xlfn.XLOOKUP(D4, Product_Master[SKU], Product_Master[Unit Price], 0) -> 15000 | K4: =H4 * J4 -> 30000 | M4: John | N4: 15000 | P4: 15000 | Q4: =Stock_Out_Log[[#This Row],[Cash]]+Stock_Out_Log[[#This Row],[Transfer]]+Stock_Out_Log[[#This Row],[POS]] -> 30000 | R4: =Stock_Out_Log[[#This Row],[Total Revenue]]-Stock_Out_Log[[#This Row],[Total Paid ]] -> 0 | S4: =K4 - (H4 * _xlfn.XLOOKUP(D4, Product_Master!B:B, Product_Master!H:H, 0)) -> 30000
B5: 46190 | C5: S00003 | D5: SKU-002 | E5: =_xlfn.XLOOKUP(D5, Product_Master[SKU], Product_Master[Parent SKU], "Unknown SKU") -> SKU-002 | F5: =_xlfn.XLOOKUP(D5, Product_Master[SKU], Product_Master[Product Name], "Unknown SKU") -> P2 | G5: =_xlfn.XLOOKUP(D5, Product_Master[SKU], Product_Master[Category], "Unknown SKU") -> Stationary | H5: 13 | I5: =Stock_Out_Log[[#This Row],[Quantity]] * _xlfn.XLOOKUP(Stock_Out_Log[[#This Row],[SKU]], Product_Master!C:C, Product_Master!G:G, 1) -> 13 | J5: =_xlfn.XLOOKUP(D5, Product_Master[SKU], Product_Master[Unit Price], 0) -> 1900 | K5: =H5 * J5 -> 24700 | M5: John | O5: 24710 | Q5: =Stock_Out_Log[[#This Row],[Cash]]+Stock_Out_Log[[#This Row],[Transfer]]+Stock_Out_Log[[#This Row],[POS]] -> 24710 | R5: =Stock_Out_Log[[#This Row],[Total Revenue]]-Stock_Out_Log[[#This Row],[Total Paid ]] -> -10 | S5: =K5 - (H5 * _xlfn.XLOOKUP(D5, Product_Master!B:B, Product_Master!H:H, 0)) -> 24700
B6: 46190 | C6: S00004 | D6: SKU-006 | E6: =_xlfn.XLOOKUP(D6, Product_Master[SKU], Product_Master[Parent SKU], "Unknown SKU") -> SKU-006 | F6: =_xlfn.XLOOKUP(D6, Product_Master[SKU], Product_Master[Product Name], "Unknown SKU") -> P6 | G6: =_xlfn.XLOOKUP(D6, Product_Master[SKU], Product_Master[Category], "Unknown SKU") -> Pasteries | H6: 9 | I6: =Stock_Out_Log[[#This Row],[Quantity]] * _xlfn.XLOOKUP(Stock_Out_Log[[#This Row],[SKU]], Product_Master!C:C, Product_Master!G:G, 1) -> 9 | J6: =_xlfn.XLOOKUP(D6, Product_Master[SKU], Product_Master[Unit Price], 0) -> 7000 | K6: =H6 * J6 -> 63000 | M6: John | N6: 63000 | Q6: =Stock_Out_Log[[#This Row],[Cash]]+Stock_Out_Log[[#This Row],[Transfer]]+Stock_Out_Log[[#This Row],[POS]] -> 63000 | R6: =Stock_Out_Log[[#This Row],[Total Revenue]]-Stock_Out_Log[[#This Row],[Total Paid ]] -> 0 | S6: =K6 - (H6 * _xlfn.XLOOKUP(D6, Product_Master!B:B, Product_Master!H:H, 0)) -> 63000
B7: 46190 | C7: S00005 | D7: SKU-004 | E7: =_xlfn.XLOOKUP(D7, Product_Master[SKU], Product_Master[Parent SKU], "Unknown SKU") -> SKU-004 | F7: =_xlfn.XLOOKUP(D7, Product_Master[SKU], Product_Master[Product Name], "Unknown SKU") -> P4 | G7: =_xlfn.XLOOKUP(D7, Product_Master[SKU], Product_Master[Category], "Unknown SKU") -> Sanitary | H7: 3 | I7: =Stock_Out_Log[[#This Row],[Quantity]] * _xlfn.XLOOKUP(Stock_Out_Log[[#This Row],[SKU]], Product_Master!C:C, Product_Master!G:G, 1) -> 3 | J7: =_xlfn.XLOOKUP(D7, Product_Master[SKU], Product_Master[Unit Price], 0) -> 5500 | K7: =H7 * J7 -> 16500 | M7: John | P7: 16500 | Q7: =Stock_Out_Log[[#This Row],[Cash]]+Stock_Out_Log[[#This Row],[Transfer]]+Stock_Out_Log[[#This Row],[POS]] -> 16500 | R7: =Stock_Out_Log[[#This Row],[Total Revenue]]-Stock_Out_Log[[#This Row],[Total Paid ]] -> 0 | S7: =K7 - (H7 * _xlfn.XLOOKUP(D7, Product_Master!B:B, Product_Master!H:H, 0)) -> 16500
B8: 46190 | C8: S00006 | D8: SKU-019-20 | E8: =_xlfn.XLOOKUP(D8, Product_Master[SKU], Product_Master[Parent SKU], "Unknown SKU") -> SKU-019 | F8: =_xlfn.XLOOKUP(D8, Product_Master[SKU], Product_Master[Product Name], "Unknown SKU") -> P20 | G8: =_xlfn.XLOOKUP(D8, Product_Master[SKU], Product_Master[Category], "Unknown SKU") -> Household | H8: 1 | I8: =Stock_Out_Log[[#This Row],[Quantity]] * _xlfn.XLOOKUP(Stock_Out_Log[[#This Row],[SKU]], Product_Master!C:C, Product_Master!G:G, 1) -> 20 | J8: =_xlfn.XLOOKUP(D8, Product_Master[SKU], Product_Master[Unit Price], 0) -> 150000 | K8: =H8 * J8 -> 150000 | M8: John | O8: 150000 | Q8: =Stock_Out_Log[[#This Row],[Cash]]+Stock_Out_Log[[#This Row],[Transfer]]+Stock_Out_Log[[#This Row],[POS]] -> 150000 | R8: =Stock_Out_Log[[#This Row],[Total Revenue]]-Stock_Out_Log[[#This Row],[Total Paid ]] -> 0 | S8: =K8 - (H8 * _xlfn.XLOOKUP(D8, Product_Master!B:B, Product_Master!H:H, 0)) -> 150000
B9: 46191 | C9: S00007 | D9: SKU-004 | E9: =_xlfn.XLOOKUP(D9, Product_Master[SKU], Product_Master[Parent SKU], "Unknown SKU") -> SKU-004 | F9: =_xlfn.XLOOKUP(D9, Product_Master[SKU], Product_Master[Product Name], "Unknown SKU") -> P4 | G9: =_xlfn.XLOOKUP(D9, Product_Master[SKU], Product_Master[Category], "Unknown SKU") -> Sanitary | H9: 5 | I9: =Stock_Out_Log[[#This Row],[Quantity]] * _xlfn.XLOOKUP(Stock_Out_Log[[#This Row],[SKU]], Product_Master!C:C, Product_Master!G:G, 1) -> 5 | J9: =_xlfn.XLOOKUP(D9, Product_Master[SKU], Product_Master[Unit Price], 0) -> 5500 | K9: =H9 * J9 -> 27500 | M9: John | O9: 27500 | Q9: =Stock_Out_Log[[#This Row],[Cash]]+Stock_Out_Log[[#This Row],[Transfer]]+Stock_Out_Log[[#This Row],[POS]] -> 27500 | R9: =Stock_Out_Log[[#This Row],[Total Revenue]]-Stock_Out_Log[[#This Row],[Total Paid ]] -> 0 | S9: =K9 - (H9 * _xlfn.XLOOKUP(D9, Product_Master!B:B, Product_Master!H:H, 0)) -> 27500
B10: 46192 | C10: S00008 | D10: SKU-001 | E10: =_xlfn.XLOOKUP(D10, Product_Master[SKU], Product_Master[Parent SKU], "Unknown SKU") -> SKU-001 | F10: =_xlfn.XLOOKUP(D10, Product_Master[SKU], Product_Master[Product Name], "Unknown SKU") -> P1 | G10: =_xlfn.XLOOKUP(D10, Product_Master[SKU], Product_Master[Category], "Unknown SKU") -> Beverage | H10: 1 | I10: =Stock_Out_Log[[#This Row],[Quantity]] * _xlfn.XLOOKUP(Stock_Out_Log[[#This Row],[SKU]], Product_Master!C:C, Product_Master!G:G, 1) -> 1 | J10: =_xlfn.XLOOKUP(D10, Product_Master[SKU], Product_Master[Unit Price], 0) -> 3000 | K10: =H10 * J10 -> 3000 | M10: John | P10: 3000 | Q10: =Stock_Out_Log[[#This Row],[Cash]]+Stock_Out_Log[[#This Row],[Transfer]]+Stock_Out_Log[[#This Row],[POS]] -> 3000 | R10: =Stock_Out_Log[[#This Row],[Total Revenue]]-Stock_Out_Log[[#This Row],[Total Paid ]] -> 0 | S10: =K10 - (H10 * _xlfn.XLOOKUP(D10, Product_Master!B:B, Product_Master!H:H, 0)) -> 3000
B11: 46193 | C11: S00009 | D11: SKU-003 | E11: =_xlfn.XLOOKUP(D11, Product_Master[SKU], Product_Master[Parent SKU], "Unknown SKU") -> SKU-003 | F11: =_xlfn.XLOOKUP(D11, Product_Master[SKU], Product_Master[Product Name], "Unknown SKU") -> P3 | G11: =_xlfn.XLOOKUP(D11, Product_Master[SKU], Product_Master[Category], "Unknown SKU") -> Household | H11: 5 | I11: =Stock_Out_Log[[#This Row],[Quantity]] * _xlfn.XLOOKUP(Stock_Out_Log[[#This Row],[SKU]], Product_Master!C:C, Product_Master!G:G, 1) -> 5 | J11: =_xlfn.XLOOKUP(D11, Product_Master[SKU], Product_Master[Unit Price], 0) -> 750 | K11: =H11 * J11 -> 3750 | M11: John | P11: 3750 | Q11: =Stock_Out_Log[[#This Row],[Cash]]+Stock_Out_Log[[#This Row],[Transfer]]+Stock_Out_Log[[#This Row],[POS]] -> 3750 | R11: =Stock_Out_Log[[#This Row],[Total Revenue]]-Stock_Out_Log[[#This Row],[Total Paid ]] -> 0 | S11: =K11 - (H11 * _xlfn.XLOOKUP(D11, Product_Master!B:B, Product_Master!H:H, 0)) -> 3750
B12: 46194 | C12: S00010 | D12: SKU-018 | E12: =_xlfn.XLOOKUP(D12, Product_Master[SKU], Product_Master[Parent SKU], "Unknown SKU") -> SKU-018 | F12: =_xlfn.XLOOKUP(D12, Product_Master[SKU], Product_Master[Product Name], "Unknown SKU") -> P18 | G12: =_xlfn.XLOOKUP(D12, Product_Master[SKU], Product_Master[Category], "Unknown SKU") -> Toiletry | H12: 1 | I12: =Stock_Out_Log[[#This Row],[Quantity]] * _xlfn.XLOOKUP(Stock_Out_Log[[#This Row],[SKU]], Product_Master!C:C, Product_Master!G:G, 1) -> 1 | J12: =_xlfn.XLOOKUP(D12, Product_Master[SKU], Product_Master[Unit Price], 0) -> 8100 | K12: =H12 * J12 -> 8100 | M12: John | N12: 8100 | Q12: =Stock_Out_Log[[#This Row],[Cash]]+Stock_Out_Log[[#This Row],[Transfer]]+Stock_Out_Log[[#This Row],[POS]] -> 8100 | R12: =Stock_Out_Log[[#This Row],[Total Revenue]]-Stock_Out_Log[[#This Row],[Total Paid ]] -> 0 | S12: =K12 - (H12 * _xlfn.XLOOKUP(D12, Product_Master!B:B, Product_Master!H:H, 0)) -> 8100
B13: 46195 | C13: S00011 | D13: SKU-013 | E13: =_xlfn.XLOOKUP(D13, Product_Master[SKU], Product_Master[Parent SKU], "Unknown SKU") -> SKU-013 | F13: =_xlfn.XLOOKUP(D13, Product_Master[SKU], Product_Master[Product Name], "Unknown SKU") -> P13 | G13: =_xlfn.XLOOKUP(D13, Product_Master[SKU], Product_Master[Category], "Unknown SKU") -> Beverage | H13: 6 | I13: =Stock_Out_Log[[#This Row],[Quantity]] * _xlfn.XLOOKUP(Stock_Out_Log[[#This Row],[SKU]], Product_Master!C:C, Product_Master!G:G, 1) -> 6 | J13: =_xlfn.XLOOKUP(D13, Product_Master[SKU], Product_Master[Unit Price], 0) -> 1000 | K13: =H13 * J13 -> 6000 | M13: John | N13: 6000 | Q13: =Stock_Out_Log[[#This Row],[Cash]]+Stock_Out_Log[[#This Row],[Transfer]]+Stock_Out_Log[[#This Row],[POS]] -> 6000 | R13: =Stock_Out_Log[[#This Row],[Total Revenue]]-Stock_Out_Log[[#This Row],[Total Paid ]] -> 0 | S13: =K13 - (H13 * _xlfn.XLOOKUP(D13, Product_Master!B:B, Product_Master!H:H, 0)) -> 6000
B14: 46196 | C14: S00012 | D14: SKU-013 | E14: =_xlfn.XLOOKUP(D14, Product_Master[SKU], Product_Master[Parent SKU], "Unknown SKU") -> SKU-013 | F14: =_xlfn.XLOOKUP(D14, Product_Master[SKU], Product_Master[Product Name], "Unknown SKU") -> P13 | G14: =_xlfn.XLOOKUP(D14, Product_Master[SKU], Product_Master[Category], "Unknown SKU") -> Beverage | H14: 4 | I14: =Stock_Out_Log[[#This Row],[Quantity]] * _xlfn.XLOOKUP(Stock_Out_Log[[#This Row],[SKU]], Product_Master!C:C, Product_Master!G:G, 1) -> 4 | J14: =_xlfn.XLOOKUP(D14, Product_Master[SKU], Product_Master[Unit Price], 0) -> 1000 | K14: =H14 * J14 -> 4000 | M14: John | N14: 4000 | Q14: =Stock_Out_Log[[#This Row],[Cash]]+Stock_Out_Log[[#This Row],[Transfer]]+Stock_Out_Log[[#This Row],[POS]] -> 4000 | R14: =Stock_Out_Log[[#This Row],[Total Revenue]]-Stock_Out_Log[[#This Row],[Total Paid ]] -> 0 | S14: =K14 - (H14 * _xlfn.XLOOKUP(D14, Product_Master!B:B, Product_Master!H:H, 0)) -> 4000
B15: 46197 | C15: S00013 | D15: SKU-004 | E15: =_xlfn.XLOOKUP(D15, Product_Master[SKU], Product_Master[Parent SKU], "Unknown SKU") -> SKU-004 | F15: =_xlfn.XLOOKUP(D15, Product_Master[SKU], Product_Master[Product Name], "Unknown SKU") -> P4 | G15: =_xlfn.XLOOKUP(D15, Product_Master[SKU], Product_Master[Category], "Unknown SKU") -> Sanitary | H15: 2 | I15: =Stock_Out_Log[[#This Row],[Quantity]] * _xlfn.XLOOKUP(Stock_Out_Log[[#This Row],[SKU]], Product_Master!C:C, Product_Master!G:G, 1) -> 2 | J15: =_xlfn.XLOOKUP(D15, Product_Master[SKU], Product_Master[Unit Price], 0) -> 5500 | K15: =H15 * J15 -> 11000 | M15: John | O15: 5000 | Q15: =Stock_Out_Log[[#This Row],[Cash]]+Stock_Out_Log[[#This Row],[Transfer]]+Stock_Out_Log[[#This Row],[POS]] -> 5000 | R15: =Stock_Out_Log[[#This Row],[Total Revenue]]-Stock_Out_Log[[#This Row],[Total Paid ]] -> 6000 | S15: =K15 - (H15 * _xlfn.XLOOKUP(D15, Product_Master!B:B, Product_Master!H:H, 0)) -> 11000
B16: 46198 | C16: S00014 | D16: SKU-019 | E16: =_xlfn.XLOOKUP(D16, Product_Master[SKU], Product_Master[Parent SKU], "Unknown SKU") -> SKU-019 | F16: =_xlfn.XLOOKUP(D16, Product_Master[SKU], Product_Master[Product Name], "Unknown SKU") -> P19 | G16: =_xlfn.XLOOKUP(D16, Product_Master[SKU], Product_Master[Category], "Unknown SKU") -> Household | H16: 1 | I16: =Stock_Out_Log[[#This Row],[Quantity]] * _xlfn.XLOOKUP(Stock_Out_Log[[#This Row],[SKU]], Product_Master!C:C, Product_Master!G:G, 1) -> 1 | J16: =_xlfn.XLOOKUP(D16, Product_Master[SKU], Product_Master[Unit Price], 0) -> 6500 | K16: =H16 * J16 -> 6500 | M16: John | O16: 6500 | Q16: =Stock_Out_Log[[#This Row],[Cash]]+Stock_Out_Log[[#This Row],[Transfer]]+Stock_Out_Log[[#This Row],[POS]] -> 6500 | R16: =Stock_Out_Log[[#This Row],[Total Revenue]]-Stock_Out_Log[[#This Row],[Total Paid ]] -> 0 | S16: =K16 - (H16 * _xlfn.XLOOKUP(D16, Product_Master!B:B, Product_Master!H:H, 0)) -> 6500
B17: 46199 | C17: S00015 | D17: SKU-001 | E17: =_xlfn.XLOOKUP(D17, Product_Master[SKU], Product_Master[Parent SKU], "Unknown SKU") -> SKU-001 | F17: =_xlfn.XLOOKUP(D17, Product_Master[SKU], Product_Master[Product Name], "Unknown SKU") -> P1 | G17: =_xlfn.XLOOKUP(D17, Product_Master[SKU], Product_Master[Category], "Unknown SKU") -> Beverage | H17: 2 | I17: =Stock_Out_Log[[#This Row],[Quantity]] * _xlfn.XLOOKUP(Stock_Out_Log[[#This Row],[SKU]], Product_Master!C:C, Product_Master!G:G, 1) -> 2 | J17: =_xlfn.XLOOKUP(D17, Product_Master[SKU], Product_Master[Unit Price], 0) -> 3000 | K17: =H17 * J17 -> 6000 | M17: John | P17: 6000 | Q17: =Stock_Out_Log[[#This Row],[Cash]]+Stock_Out_Log[[#This Row],[Transfer]]+Stock_Out_Log[[#This Row],[POS]] -> 6000 | R17: =Stock_Out_Log[[#This Row],[Total Revenue]]-Stock_Out_Log[[#This Row],[Total Paid ]] -> 0 | S17: =K17 - (H17 * _xlfn.XLOOKUP(D17, Product_Master!B:B, Product_Master!H:H, 0)) -> 6000
B18: 46200 | C18: S00016 | D18: SKU-004 | E18: =_xlfn.XLOOKUP(D18, Product_Master[SKU], Product_Master[Parent SKU], "Unknown SKU") -> SKU-004 | F18: =_xlfn.XLOOKUP(D18, Product_Master[SKU], Product_Master[Product Name], "Unknown SKU") -> P4 | G18: =_xlfn.XLOOKUP(D18, Product_Master[SKU], Product_Master[Category], "Unknown SKU") -> Sanitary | H18: 7 | I18: =Stock_Out_Log[[#This Row],[Quantity]] * _xlfn.XLOOKUP(Stock_Out_Log[[#This Row],[SKU]], Product_Master!C:C, Product_Master!G:G, 1) -> 7 | J18: =_xlfn.XLOOKUP(D18, Product_Master[SKU], Product_Master[Unit Price], 0) -> 5500 | K18: =H18 * J18 -> 38500 | M18: John | O18: 20000 | Q18: =Stock_Out_Log[[#This Row],[Cash]]+Stock_Out_Log[[#This Row],[Transfer]]+Stock_Out_Log[[#This Row],[POS]] -> 20000 | R18: =Stock_Out_Log[[#This Row],[Total Revenue]]-Stock_Out_Log[[#This Row],[Total Paid ]] -> 18500 | S18: =K18 - (H18 * _xlfn.XLOOKUP(D18, Product_Master!B:B, Product_Master!H:H, 0)) -> 38500
B19: 46201 | C19: S00017 | D19: SKU-016 | E19: =_xlfn.XLOOKUP(D19, Product_Master[SKU], Product_Master[Parent SKU], "Unknown SKU") -> SKU-016 | F19: =_xlfn.XLOOKUP(D19, Product_Master[SKU], Product_Master[Product Name], "Unknown SKU") -> P16 | G19: =_xlfn.XLOOKUP(D19, Product_Master[SKU], Product_Master[Category], "Unknown SKU") -> Pasteries | H19: 55 | I19: =Stock_Out_Log[[#This Row],[Quantity]] * _xlfn.XLOOKUP(Stock_Out_Log[[#This Row],[SKU]], Product_Master!C:C, Product_Master!G:G, 1) -> 55 | J19: =_xlfn.XLOOKUP(D19, Product_Master[SKU], Product_Master[Unit Price], 0) -> 5900 | K19: =H19 * J19 -> 324500 | M19: John | N19: 10000 | Q19: =Stock_Out_Log[[#This Row],[Cash]]+Stock_Out_Log[[#This Row],[Transfer]]+Stock_Out_Log[[#This Row],[POS]] -> 10000 | R19: =Stock_Out_Log[[#This Row],[Total Revenue]]-Stock_Out_Log[[#This Row],[Total Paid ]] -> 314500 | S19: =K19 - (H19 * _xlfn.XLOOKUP(D19, Product_Master!B:B, Product_Master!H:H, 0)) -> 324500
B20: 46202 | C20: S00018 | D20: SKU-003 | E20: =_xlfn.XLOOKUP(D20, Product_Master[SKU], Product_Master[Parent SKU], "Unknown SKU") -> SKU-003 | F20: =_xlfn.XLOOKUP(D20, Product_Master[SKU], Product_Master[Product Name], "Unknown SKU") -> P3 | G20: =_xlfn.XLOOKUP(D20, Product_Master[SKU], Product_Master[Category], "Unknown SKU") -> Household | H20: 1 | I20: =Stock_Out_Log[[#This Row],[Quantity]] * _xlfn.XLOOKUP(Stock_Out_Log[[#This Row],[SKU]], Product_Master!C:C, Product_Master!G:G, 1) -> 1 | J20: =_xlfn.XLOOKUP(D20, Product_Master[SKU], Product_Master[Unit Price], 0) -> 750 | K20: =H20 * J20 -> 750 | M20: John | P20: 750 | Q20: =Stock_Out_Log[[#This Row],[Cash]]+Stock_Out_Log[[#This Row],[Transfer]]+Stock_Out_Log[[#This Row],[POS]] -> 750 | R20: =Stock_Out_Log[[#This Row],[Total Revenue]]-Stock_Out_Log[[#This Row],[Total Paid ]] -> 0 | S20: =K20 - (H20 * _xlfn.XLOOKUP(D20, Product_Master!B:B, Product_Master!H:H, 0)) -> 750
B21: 46203 | C21: S00019 | D21: SKU-018 | E21: =_xlfn.XLOOKUP(D21, Product_Master[SKU], Product_Master[Parent SKU], "Unknown SKU") -> SKU-018 | F21: =_xlfn.XLOOKUP(D21, Product_Master[SKU], Product_Master[Product Name], "Unknown SKU") -> P18 | G21: =_xlfn.XLOOKUP(D21, Product_Master[SKU], Product_Master[Category], "Unknown SKU") -> Toiletry | H21: 2 | I21: =Stock_Out_Log[[#This Row],[Quantity]] * _xlfn.XLOOKUP(Stock_Out_Log[[#This Row],[SKU]], Product_Master!C:C, Product_Master!G:G, 1) -> 2 | J21: =_xlfn.XLOOKUP(D21, Product_Master[SKU], Product_Master[Unit Price], 0) -> 8100 | K21: =H21 * J21 -> 16200 | M21: John | O21: 16200 | Q21: =Stock_Out_Log[[#This Row],[Cash]]+Stock_Out_Log[[#This Row],[Transfer]]+Stock_Out_Log[[#This Row],[POS]] -> 16200 | R21: =Stock_Out_Log[[#This Row],[Total Revenue]]-Stock_Out_Log[[#This Row],[Total Paid ]] -> 0 | S21: =K21 - (H21 * _xlfn.XLOOKUP(D21, Product_Master!B:B, Product_Master!H:H, 0)) -> 16200
B22: 46204 | C22: S00020 | D22: SKU-006 | E22: =_xlfn.XLOOKUP(D22, Product_Master[SKU], Product_Master[Parent SKU], "Unknown SKU") -> SKU-006 | F22: =_xlfn.XLOOKUP(D22, Product_Master[SKU], Product_Master[Product Name], "Unknown SKU") -> P6 | G22: =_xlfn.XLOOKUP(D22, Product_Master[SKU], Product_Master[Category], "Unknown SKU") -> Pasteries | H22: 3 | I22: =Stock_Out_Log[[#This Row],[Quantity]] * _xlfn.XLOOKUP(Stock_Out_Log[[#This Row],[SKU]], Product_Master!C:C, Product_Master!G:G, 1) -> 3 | J22: =_xlfn.XLOOKUP(D22, Product_Master[SKU], Product_Master[Unit Price], 0) -> 7000 | K22: =H22 * J22 -> 21000 | M22: John | N22: 21000 | Q22: =Stock_Out_Log[[#This Row],[Cash]]+Stock_Out_Log[[#This Row],[Transfer]]+Stock_Out_Log[[#This Row],[POS]] -> 21000 | R22: =Stock_Out_Log[[#This Row],[Total Revenue]]-Stock_Out_Log[[#This Row],[Total Paid ]] -> 0 | S22: =K22 - (H22 * _xlfn.XLOOKUP(D22, Product_Master!B:B, Product_Master!H:H, 0)) -> 21000
B23: 46205 | C23: S00021 | D23: SKU-005 | E23: =_xlfn.XLOOKUP(D23, Product_Master[SKU], Product_Master[Parent SKU], "Unknown SKU") -> SKU-005 | F23: =_xlfn.XLOOKUP(D23, Product_Master[SKU], Product_Master[Product Name], "Unknown SKU") -> P5 | G23: =_xlfn.XLOOKUP(D23, Product_Master[SKU], Product_Master[Category], "Unknown SKU") -> Toiletry | H23: 1 | I23: =Stock_Out_Log[[#This Row],[Quantity]] * _xlfn.XLOOKUP(Stock_Out_Log[[#This Row],[SKU]], Product_Master!C:C, Product_Master!G:G, 1) -> 1 | J23: =_xlfn.XLOOKUP(D23, Product_Master[SKU], Product_Master[Unit Price], 0) -> 4500 | K23: =H23 * J23 -> 4500 | M23: John | P23: 4500 | Q23: =Stock_Out_Log[[#This Row],[Cash]]+Stock_Out_Log[[#This Row],[Transfer]]+Stock_Out_Log[[#This Row],[POS]] -> 4500 | R23: =Stock_Out_Log[[#This Row],[Total Revenue]]-Stock_Out_Log[[#This Row],[Total Paid ]] -> 0 | S23: =K23 - (H23 * _xlfn.XLOOKUP(D23, Product_Master!B:B, Product_Master!H:H, 0)) -> 4500
C24: S00022 | D24: SKU-013 | E24: =_xlfn.XLOOKUP(D24, Product_Master[SKU], Product_Master[Parent SKU], "Unknown SKU") -> SKU-013 | F24: =_xlfn.XLOOKUP(D24, Product_Master[SKU], Product_Master[Product Name], "Unknown SKU") -> P13 | G24: =_xlfn.XLOOKUP(D24, Product_Master[SKU], Product_Master[Category], "Unknown SKU") -> Beverage | H24: 52 | I24: =Stock_Out_Log[[#This Row],[Quantity]] * _xlfn.XLOOKUP(Stock_Out_Log[[#This Row],[SKU]], Product_Master!C:C, Product_Master!G:G, 1) -> 52 | J24: =_xlfn.XLOOKUP(D24, Product_Master[SKU], Product_Master[Unit Price], 0) -> 1000 | K24: =H24 * J24 -> 52000 | M24: Sarah | N24: 20000 | P24: 32000 | Q24: =Stock_Out_Log[[#This Row],[Cash]]+Stock_Out_Log[[#This Row],[Transfer]]+Stock_Out_Log[[#This Row],[POS]] -> 52000 | R24: =Stock_Out_Log[[#This Row],[Total Revenue]]-Stock_Out_Log[[#This Row],[Total Paid ]] -> 0 | S24: =K24 - (H24 * _xlfn.XLOOKUP(D24, Product_Master!B:B, Product_Master!H:H, 0)) -> 52000

Sheet Sales Reconciliation
C1: 46190
B2: Cashiers Registry | G2: Cashier & Bank Reconciliation
B3: Cashier 1 | C3: Registers | D3: Physical Values | E3: System Value
C4: John | H4: Cashiers Report | L4: POS MACHINE REPORTS
C5: CASH | D5: 31500 | E5: =SUMIFS(Sales!P:P, Sales!B:B, $C$1, Sales!M:M, C4) -> 31500 | H5: REGISTER | I5: POS-TERMINALS | J5: BANK-TRANSFERS | L5: Machine(s) | M5: PURCHASES | N5: TRANSFER
C6: POS-TERMINAL | D6: 112700 | E6: =SUMIFS(Sales!N:N, Sales!B:B, $C$1, Sales!M:M, C4) -> 78000 | H6: Cashier 1 | I6: =D6 -> 112700 | J6: =D7 -> 153000 | L6: MONIEPOINT | M6: 65000 | N6: 87700
C7: BANK-TRANSFERS | D7: 153000 | E7: =SUMIFS(Sales!O:O, Sales!B:B, $C$1, Sales!M:M, C4) -> 187710 | H7: Cashier 2 | I7: =D15 -> 0 | J7: =D16 -> 0 | L7: OPAY | M7: 13300 | N7: 100000
C8: TOTAL | D8: =SUM(D5:D7) -> 297200 | E8: =SUM(E5:E7) -> 297210 | H8: Total | I8: =SUM(I6:I7) -> 112700 | J8: =SUM(J6:J7) -> 153000 | L8: Total | M8: =M7+M6 -> 78300 | N8: =N7+N6 -> 187700
C9: Diff (+)(-) | D9: =D8-E8 -> -10 | H9: Grand Total | I9: =I8+J8 -> 265700 | K9: =M9-I9 -> 300 | L9: Grand Total | M9: =M8+N8 -> 266000
B12: Cashier 2 | C12: Registers | D12: Physical Values | E12: System Value | I12: Cash Summary | L12: Payment Summary
C13: Name | I13: Sys.Cash | J13: =E5+E14 -> 31500 | L13: T. Cash | M13: =D5+D14 -> 31500
C14: CASH | E14: =SUMIFS(Sales!P:P, Sales!B:B, $C$1, Sales!M:M, C13) -> 0 | I14: Phy. Cash | J14: =D5+D14 -> 31500 | L14: T. POS | M14: =D6+D15 -> 112700
C15: POS-TERMINAL | E15: =SUMIFS(Sales!N:N, Sales!B:B, $C$1, Sales!M:M, C13) -> 0 | I15: Expenses | L15: T. Trfs | M15: =D7+D16 -> 153000
C16: BANK-TRANSFERS | E16: =SUMIFS(Sales!O:O, Sales!B:B, $C$1, Sales!M:M, C13) -> 0 | I16: Cash @ Hand | J16: =J14-J15 -> 31500 | L16: G. Total | M16: =SUM(M13:M15) -> 297200
C17: TOTAL | D17: =SUM(D14:D16) -> 0 | E17: =SUM(E14:E16) -> 0
C18: Diff (+)(-) | D18: =D17-E17 -> 0

Sheet Expense 
B1: Expense Sheet
A2: Date | B2: Item | C2: Category | D2: Payment Type | E2: Amount
A3: 46023 | B3: Transport | C3: Logistics | D3: Cash | E3: 2000
A4: 46024 | B4: Airtime for office phone | C4: Expenses | D4: Cash | E4: 1000
A5: 46025 | B5: 60 Leaves for Account Record | C5: Expenses | D5: Cash | E5: 500

Sheet Accounting
B2: Income statement
B3: Revenue | F3: Cash Flow | J3: Balance Sheet
B4: Returns(B&Ds) | F4: Beginning Cash | G4: input | J4: Cash | K4: =Cash Flow Ending Cash
B5: Net Sales | C5: =C3-C4 -> 0 | F5: Net Income | G5: =C28 -> 0 | J5: Receivables | K5: input
F6: Accounts Payable | J6: Inventory | K6: input
B7: Beginning Inventory | F7: Accounts Receivable | J7: Equipment | K7: input
B8: Purchases | F8: Depreciation | J8: TOTAL ASSETS | K8: =SUM(K4:K7) -> 0
B9: Closing Inventory Value | F9: Non-cash Adjustments | G9: =SUM(G6:G8) -> 0
B10: Cost of Goods Sold | C10: =C7+C8-C9 -> 0 | F10: Operating Cash | G10: =G9+G5 -> 0 | J10: Supplier Payables | K10: input
F11: Investing Cash | G11: input | J11: Staff Salaries Owed | K11: input
B12: Gross Profit. | C12: =C5-C10 -> 0 | F12: Financing Cash | G12: input | J12: Loans | K12: input
F13: Net Change | G13: =SUM(G10:G12) -> 0 | J13: TOTAL LIABILITIES | K13: =SUM(K10:K12) -> 0
B14: Salaries/Wages | F14: Ending Cash | G14: =G13+G4 -> #VALUE!
B15: Utility | J15: Owner Capital | K15: input
B16: Rent | J16: Retained Profit | K16: =Net Profit
B17: Maintainance | J17: TOTAL EQUITY | K17: =SUM(K15:K16) -> 0
B18: Logistics
B19: Others
B20: Total Operating Expense | C20: =SUM(C14:C19) -> 0
B22: Operating Profit | C22: =C12-C20 -> 0
B24: Other Income
B25: Income (before Taxes) | C25: =C24+C22 -> 0
B26: Acured tax
B28: Net Profit | C28: =C25-C26 -> 0

Sheet Payroll
C1: Payroll Summary
B2: DEPARTMENT/NAME | C2: POSITION | D2: BANK DETAILS | E2: ARREARS | F2: Column1 | G2: SHORTFALLS | H2: LATENESS | I2: ABSENT | J2: IOU | K2: SURCHARGE | L2: TAX | M2: GROSS PAY | N2: NET PAY
B3: ADMINSTRATIVE
B4: Samuel John | C4: Manager | D4: Fidelity - xxxxxxxxx | E4: 10000 | L4: 5000 | M4: 500000 | N4: =M4-E4+F4-G4-H4-I4-J4-K4-L4 -> 485000
B5: Captin Jack | C5: Ass. manager | D5: Access- xxxxxxxxx | E5: 10000 | G5: 1000 | M5: 400000 | N5: =M5-E5+F5-G5-H5-I5-J5-K5-L5 -> 389000
B7: INVENTORY
B8: Success Grace | C8: Head Inventory/Oficcer | D8: First Bank- xxxxxxxxx | E8: 10000 | G8: 500 | M8: 350000 | N8: =M8-E8+F8-G8-H8-I8-J8-K8-L8 -> 339500
B9: Magnus Olive | C9: Inventory Personnel | D9: Opay - xxxxxxxxx | E9: 10000 | H9: 4000 | M9: 300000 | N9: =M9-E9+F9-G9-H9-I9-J9-K9-L9 -> 286000

Sheet Back_End
A1: Master Categories
A2: Beverage
A3: Stationary
A4: Household
A5: Pharmaceuticals
A6: Sanitary
A7: Toiletries
A8: Pastries

Sheet Suppliers
B1: Suppliers Details
A2: Vendors Name | B2: Address | C2: Phone | D2: Website | E2: Bank details
A3: Bederco | B3: 55 Airplan | C3: (+234)8059834678 | D3: jigi.com | E3: Access - 1086358903
A4: King James | B4: 22 Apapa | C4: (+234)9063437822 | D4: fifi.ng | E4: Opay - 78903673764
A5: Gift Ventures | B5: 16 Caroline | C5: (+234)8075437925 | D5: huji.com | E5: Eco - 090865370
A6: Great Ventures | B6: Maitama | C6: (+234)9063437822 | D6: Hawayi.entertaiment.com | E6: UBA - 090865370

Sheet Adjustments
A1: SKU | B1: Product Name | C1: Quantity | D1: Type | E1: Reason
A2: SKU-001 | B2: =_xlfn.XLOOKUP(A2, Product_Master[SKU], Product_Master[Product Name], "Unknown SKU") -> P1 | C2: 3 | D2: Scrap | E2: Bad & Damaged
A3: SKU-003 | B3: =_xlfn.XLOOKUP(A3, Product_Master[SKU], Product_Master[Product Name], "Unknown SKU") -> P3 | C3: 1 | D3: Adjustment - Add | E3: Found
A4: SKU-005 | B4: =_xlfn.XLOOKUP(A4, Product_Master[SKU], Product_Master[Product Name], "Unknown SKU") -> P5 | C4: 2 | D4: Adjustment (-) | E4: Stolen
